<mujoco model="rototranslational_bar">
    <compiler angle="radian" inertiafromgeom="true"/>
    <option timestep="0.02" gravity="0 0 -9.81"/>
    <default>
        <geom contype="0" friction="100 100 100" rgba="0.7 0.7 0 1"/>
  </default>
    <asset>
        <texture name="grid" type="2d" builtin="checker" width="512" height="512" rgb1="0.8 0.8 0.8" rgb2="0.5 0.9 0.6" />
        <material name="grid_material" texture="grid" texrepeat="5 5" />
    </asset>
    <!-- World Elements -->
    <worldbody>
        <!-- XY Plane -->
        <geom type="plane" size="5 5 0.3" rgba="1 1 1 1" material="grid_material"/>

        <!-- Bar Definition -->

        <body name="left_bar" pos="-0.5 0 0.1">
            <!-- Bar Geometry -->
            <geom type="capsule" size="0.05 0.45" rgba="0 1 0 1" euler="0 1.5708 0"/>

            <!-- Joints for Left Movement -->
            <joint name="left_joint_x" type="slide" axis="1 0 0" pos="-0.5 0 0" range="-5 5"/>
            <joint name="left_joint_y" type="slide" axis="0 1 0" pos="-0.5 0 0" range="-5 5"/>
            <joint name="left_rotation_motor" type="hinge" axis="0 0 1" pos="-0.5 0 0"/>
            <!-- <site name="left_bar" pos="-0.5 0 0" size="0.1 0.1 0.1" type="sphere" rgba="1 0 0 0.5"/>-->

        </body>
        <body name="right_bar" pos="0.5 0 0.1">
            <!-- Bar Geometry -->
            <geom type="capsule" size="0.05 0.45" rgba="1 0 0 1" euler="0 1.5708 0"/>

            <!-- Joints for Right Movement -->
            <joint name="right_joint_x" type="slide" axis="1 0 0" pos="0.5 0 0" range="-5 5"/>
            <joint name="right_joint_y" type="slide" axis="0 1 0" pos="0.5 0 0" range="-5 5"/>
            <joint name="right_rotation_motor" type="hinge" axis="0 0 1" pos="0.5 0 0"/>
            <!-- <site name="right_bar" pos="0.5 0 0" size="0.1 0.1 0.1" type="sphere" rgba="1 0 0 0.5"/>-->


        </body>

    </worldbody>

    <equality>
      <weld name="left_bar_toright_bar" body1="left_bar" body2="right_bar"/>
    </equality>


    <!-- Actuator Definition -->
    <actuator>
        <!-- Forces Applied to Left Extremity -->
        <motor name="green_force_x" joint="left_joint_x" gear="2.5" ctrlrange="-10 10"/>
        <motor name="green_force_y" joint="left_joint_y" gear="2.5" ctrlrange="-10 10"/>
        <motor name="red_force_x" joint="right_joint_x" gear="2.5" ctrlrange="-10 10"/> 
        <motor name="red_force_y" joint="right_joint_y" gear="2.5" ctrlrange="-10 10"/>

    </actuator>
</mujoco>
